[2021-05-27 14:07:22,850] {taskinstance.py:876} INFO - Dependencies all met for <TaskInstance: dag_transfers_scraping.scrape_transfers 2021-05-27T14:07:20.869300+00:00 [queued]>
[2021-05-27 14:07:22,862] {taskinstance.py:876} INFO - Dependencies all met for <TaskInstance: dag_transfers_scraping.scrape_transfers 2021-05-27T14:07:20.869300+00:00 [queued]>
[2021-05-27 14:07:22,862] {taskinstance.py:1067} INFO - 
--------------------------------------------------------------------------------
[2021-05-27 14:07:22,862] {taskinstance.py:1068} INFO - Starting attempt 1 of 1
[2021-05-27 14:07:22,862] {taskinstance.py:1069} INFO - 
--------------------------------------------------------------------------------
[2021-05-27 14:07:22,869] {taskinstance.py:1087} INFO - Executing <Task(PythonOperator): scrape_transfers> on 2021-05-27T14:07:20.869300+00:00
[2021-05-27 14:07:22,879] {standard_task_runner.py:52} INFO - Started process 75698 to run task
[2021-05-27 14:07:22,884] {standard_task_runner.py:76} INFO - Running: ['***', 'tasks', 'run', 'dag_transfers_scraping', 'scrape_transfers', '2021-05-27T14:07:20.869300+00:00', '--job-id', '61', '--pool', 'default_pool', '--raw', '--subdir', 'DAGS_FOLDER/dag_transfers_scraping.py', '--cfg-path', '/tmp/tmpw69oncft', '--error-file', '/tmp/tmphptk3q35']
[2021-05-27 14:07:22,884] {standard_task_runner.py:77} INFO - Job 61: Subtask scrape_transfers
[2021-05-27 14:07:22,912] {logging_mixin.py:104} INFO - Running <TaskInstance: dag_transfers_scraping.scrape_transfers 2021-05-27T14:07:20.869300+00:00 [running]> on host f7393dd572fa
[2021-05-27 14:07:22,946] {taskinstance.py:1282} INFO - Exporting the following env vars:
AIRFLOW_CTX_DAG_OWNER=***
AIRFLOW_CTX_DAG_ID=dag_transfers_scraping
AIRFLOW_CTX_TASK_ID=scrape_transfers
AIRFLOW_CTX_EXECUTION_DATE=2021-05-27T14:07:20.869300+00:00
AIRFLOW_CTX_DAG_RUN_ID=manual__2021-05-27T14:07:20.869300+00:00
[2021-05-27 14:07:25,927] {taskinstance.py:1481} ERROR - Task failed with exception
Traceback (most recent call last):
  File "/home/airflow/.local/lib/python3.6/site-packages/airflow/models/taskinstance.py", line 1137, in _run_raw_task
    self._prepare_and_execute_task_with_callbacks(context, task)
  File "/home/airflow/.local/lib/python3.6/site-packages/airflow/models/taskinstance.py", line 1311, in _prepare_and_execute_task_with_callbacks
    result = self._execute_task(context, task_copy)
  File "/home/airflow/.local/lib/python3.6/site-packages/airflow/models/taskinstance.py", line 1341, in _execute_task
    result = task_copy.execute(context=context)
  File "/home/airflow/.local/lib/python3.6/site-packages/airflow/operators/python.py", line 150, in execute
    return_value = self.execute_callable()
  File "/home/airflow/.local/lib/python3.6/site-packages/airflow/operators/python.py", line 161, in execute_callable
    return self.python_callable(*self.op_args, **self.op_kwargs)
  File "/opt/airflow/dags/etl_scripts/transfers_scraping_etl.py", line 88, in scrape_transfers
    write_to_CSV(self, df)
NameError: name 'write_to_CSV' is not defined
[2021-05-27 14:07:25,928] {taskinstance.py:1531} INFO - Marking task as FAILED. dag_id=dag_transfers_scraping, task_id=scrape_transfers, execution_date=20210527T140720, start_date=20210527T140722, end_date=20210527T140725
[2021-05-27 14:07:25,947] {local_task_job.py:151} INFO - Task exited with return code 1
